<?xml version="1.0" ?>
<!--simple pbot-->

<robot name="PBot_description">
    <link name="base_link">
        <inertial>
            <origin xyz="0.0 0.0 0.0" rpy="0 0 0" />
            <mass value="0.1" />
            <inertia ixx="0.1" iyy="0.1" izz="0.1" ixy="0" ixz="0" iyz="0" />
        </inertial>
    </link>
    <link name="cube_link">
        <inertial>
            <origin xyz="0.0 0.0 -1.0" rpy="0 0 0" />
            <mass value="1.0" />
            <inertia ixx="0.1" iyy="0.1" izz="0.1" ixy="0" ixz="0" iyz="0" />
        </inertial>
        <visual>
            <origin xyz="0.0 0.0 0.0" rpy="0 0 0" />
            <geometry>
                <box size="0.1 0.1 0.1"/>
            </geometry>
        </visual>
    </link>

    <joint name="j0" type="prismatic">
        <parent link="base_link" />
        <child link="cube_link" />
        <origin xyz="0.000000 0.000000 0.05" rpy="-0.000000 0.000000 -0.000000" />
        <axis xyz="0 0 1"/>
        <limit lower="-2.967" upper="2.967" effort="176" velocity="1.7104" />
    </joint>
</robot>
